<sdf version='1.6'>
  <model name='sudo'>
    <link name='chassis'>
      <sensor name='chassis_contact' type='contact'>
        <update_rate>30</update_rate>
        <contact>
          <collision>collision</collision>
          <topic>__default_topic__</topic>
        </contact>
        <plugin name='contact_sensor' filename='libcontact.so'/>
      </sensor>
      <pose frame=''>0 0 0.16 0 -0 0</pose>
      <inertial>
        <mass>6</mass>
        <inertia>
          <ixx>0.07</ixx>
          <iyy>0.08</iyy>
          <izz>0.1</izz>
          <ixy>0</ixy>
          <ixz>0</ixz>
          <iyz>0</iyz>
        </inertia>
      </inertial>
      <collision name='collision'>
        <geometry>
          <box>
            <size>0.485 0.25 0.17</size>
          </box>
        </geometry>
      </collision>
      <visual name='visual'>
        <pose frame=''>0 0 0.04 0 -0 0</pose>
        <geometry>
          <mesh>
            <uri>model://pioneer2dx/meshes/chassis.dae</uri>
          </mesh>
        </geometry>
      </visual>
      <collision name='collision'>
        <pose frame=''>-0.2 0 -0.12 0 -0 0</pose>
        <geometry>
          <sphere>
            <radius>0.04</radius>
          </sphere>
        </geometry>
        <surface>
          <friction>
            <ode>
              <mu>0</mu>
              <mu2>0</mu2>
              <slip1>inf</slip1>
              <slip2>inf</slip2>
            </ode>
          </friction>
        </surface>
      </collision>
      <visual name='castor_visual'>
        <pose frame=''>-0.2 0 -0.12 0 -0 0</pose>
        <geometry>
          <sphere>
            <radius>0.04</radius>
          </sphere>
        </geometry>
        <material>
          <script>
            <uri>file://media/materials/scripts/gazebo.material</uri>
            <name>Gazebo/FlatBlack</name>
          </script>
        </material>
      </visual>
    </link>
    <link name='right_wheel'>
      <pose frame=''>0.1 -0.17 0.11 -0 1.5707 1.5707</pose>
      <inertial>
        <mass>0.5</mass>
        <inertia>
          <ixx>0.07</ixx>
          <iyy>0.08</iyy>
          <izz>0.1</izz>
          <ixy>0</ixy>
          <ixz>0</ixz>
          <iyz>0</iyz>
        </inertia>
      </inertial>
      <collision name='collision'>
        <geometry>
          <cylinder>
            <radius>0.11</radius>
            <length>0.05</length>
          </cylinder>
        </geometry>
        <surface>
          <friction>
            <ode>
              <mu>inf</mu>
            </ode>
          </friction>
        </surface>
      </collision>
      <visual name='visual'>
        <geometry>
          <cylinder>
            <radius>0.11</radius>
            <length>0.05</length>
          </cylinder>
        </geometry>
        <material>
          <script>
            <uri>file://media/materials/scripts/gazebo.material</uri>
            <name>Gazebo/FlatBlack</name>
          </script>
        </material>
      </visual>
    </link>
    <link name='left_wheel'>
      <pose frame=''>0.1 0.17 0.11 -0 1.5707 1.5707</pose>
      <inertial>
        <mass>0.5</mass>
        <inertia>
          <ixx>0.07</ixx>
          <iyy>0.08</iyy>
          <izz>0.1</izz>
          <ixy>0</ixy>
          <ixz>0</ixz>
          <iyz>0</iyz>
        </inertia>
      </inertial>
      <collision name='collision'>
        <geometry>
          <cylinder>
            <radius>0.11</radius>
            <length>0.05</length>
          </cylinder>
        </geometry>
        <surface>
          <friction>
            <ode>
              <mu>inf</mu>
            </ode>
          </friction>
        </surface>
      </collision>
      <visual name='visual'>
        <geometry>
          <cylinder>
            <radius>0.11</radius>
            <length>0.05</length>
          </cylinder>
        </geometry>
        <material>
          <script>
            <uri>file://media/materials/scripts/gazebo.material</uri>
            <name>Gazebo/FlatBlack</name>
          </script>
        </material>
      </visual>
    </link>
    <link name='sick_laser'>
      <pose frame=''>0 0 0.3 0 -0 3.14</pose>
      <inertial>
        <mass>0.1</mass>
        <inertia>
          <ixx>0.07</ixx>
          <iyy>0.08</iyy>
          <izz>0.1</izz>
          <ixy>0</ixy>
          <ixz>0</ixz>
          <iyz>0</iyz>
        </inertia>
      </inertial>
      <visual name='visual'>
        <geometry>
          <mesh>
            <uri>model://hokuyo/meshes/hokuyo.dae</uri>
          </mesh>
        </geometry>
      </visual>
      <sensor name='head_hokuyo_sensor' type='gpu_ray'>
        <pose frame=''>0 0 0 0 -0 0</pose>
        <visualize>0</visualize>
        <update_rate>30</update_rate>
        <ray>
          <scan>
            <horizontal>
              <samples>360</samples>
              <resolution>1</resolution>
              <min_angle>-3.14</min_angle>
              <max_angle>3.14</max_angle>
            </horizontal>
          </scan>
          <range>
            <min>0.05</min>
            <max>10</max>
            <resolution>0.01</resolution>
          </range>
          <noise>
            <type>gaussian</type>
            <mean>0</mean>
            <stddev>0.01</stddev>
          </noise>
        </ray>
        <plugin name='gazebo_ros_head_hokuyo_controller' filename='libgazebo_ros_gpu_laser.so'>
          <topicName>/sudo/laser/scan</topicName>
          <frameName>laser_link</frameName>
        </plugin>
      </sensor>
    </link>
    <link name='cam_link'>
      <pose frame=''>0 0 1 0 -0 0</pose>
      <inertial>
        <mass>0.1</mass>
        <inertia>
          <ixx>0.07</ixx>
          <iyy>0.08</iyy>
          <izz>0.1</izz>
          <ixy>0</ixy>
          <ixz>0</ixz>
          <iyz>0</iyz>
        </inertia>
      </inertial>
      <collision name='collision'>
        <geometry>
          <box>
            <size>0.029 0.068 0.04</size>
          </box>
        </geometry>
      </collision>
      <visual name='visual'>
        <geometry>
          <box>
            <size>0.029 0.068 0.04</size>
          </box>
        </geometry>
      </visual>
      <sensor name='camera' type='camera'>
        <camera name='__default__'>
          <horizontal_fov>1.047</horizontal_fov>
          <image>
            <width>320</width>
            <height>240</height>
          </image>
          <clip>
            <near>0.05</near>
            <far>10</far>
          </clip>
        </camera>
        <always_on>1</always_on>
        <update_rate>30</update_rate>
        <visualize>1</visualize>
        <plugin name='camera_controller' filename='libgazebo_ros_camera.so'>
          <alwaysOn>true</alwaysOn>
          <updateRate>30.0</updateRate>
          <cameraName>sudo/bottom_webcam</cameraName>
          <imageTopicName>image_raw</imageTopicName>
          <cameraInfoTopicName>camera_info</cameraInfoTopicName>
          <frameName>webcam_link</frameName>
          <hackBaseline>0.07</hackBaseline>
          <distortionK1>0.0</distortionK1>
          <distortionK2>0.0</distortionK2>
          <distortionK3>0.0</distortionK3>
          <distortionT1>0.0</distortionT1>
          <distortionT2>0.0</distortionT2>
        </plugin>
      </sensor>
    </link>
    <joint name='laser_to_chassis' type='revolute'>
      <pose frame=''>0 0 0 0 -0 0</pose>
      <child>sick_laser</child>
      <parent>chassis</parent>
      <axis>
        <xyz>0 0 1</xyz>
        <limit>
          <upper>0</upper>
          <lower>0</lower>
        </limit>
        <use_parent_model_frame>0</use_parent_model_frame>
      </axis>
    </joint>
    <joint name='cam_link_to_chassis' type='revolute'>
      <pose frame=''>0 0 1 0 -0 0</pose>
      <child>cam_link</child>
      <parent>chassis</parent>
      <axis>
        <xyz>0 0 1</xyz>
        <limit>
          <upper>0</upper>
          <lower>0</lower>
        </limit>
        <use_parent_model_frame>0</use_parent_model_frame>
      </axis>
    </joint>
    <joint name='left_wheel_hinge' type='revolute'>
      <pose frame=''>0 0 0.03 0 -0 0</pose>
      <child>left_wheel</child>
      <parent>chassis</parent>
      <axis>
        <xyz>0 1 0</xyz>
        <use_parent_model_frame>0</use_parent_model_frame>
        <limit>
          <lower>-1e+16</lower>
          <upper>1e+16</upper>
        </limit>
      </axis>
    </joint>
    <joint name='right_wheel_hinge' type='revolute'>
      <pose frame=''>0 0 -0.03 0 -0 0</pose>
      <child>right_wheel</child>
      <parent>chassis</parent>
      <axis>
        <xyz>0 1 0</xyz>
        <use_parent_model_frame>0</use_parent_model_frame>
        <limit>
          <lower>-1e+16</lower>
          <upper>1e+16</upper>
        </limit>
      </axis>
    </joint>
    <plugin name='object_controller' filename='libgazebo_ros_planar_move.so'>
      <odometryRate>20.0</odometryRate>
      <robotBaseFrame>base_link</robotBaseFrame>
    </plugin>
  </model>
</sdf>
